<mujoco model="base">
  <compiler angle="radian" meshdir="meshes/"/>

  <option impratio="20" density="1.2" viscosity="2e-05" cone="elliptic"/>

  <size njmax="5000" nconmax="5000"/>

  <visual>
    <map znear="0.001"/>
  </visual>

  <asset>
    <texture type="skybox" builtin="gradient" rgb1="0.9 0.9 1" rgb2="0.2 0.3 0.4" width="256" height="1536"/>
    <texture type="2d" name="texplane" file="C:\Users/jeise/PycharmProjects/RobotLearningProject/.venv/Lib/site-packages/robosuite/models/assets/textures/light-gray-floor-tile.png"/>
    <texture type="cube" name="tex-ceramic" file="C:\Users/jeise/PycharmProjects/RobotLearningProject/.venv/Lib/site-packages/robosuite/models/assets/textures/ceramic.png"/>
    <texture type="cube" name="tex-steel-brushed" file="C:\Users/jeise/PycharmProjects/RobotLearningProject/.venv/Lib/site-packages/robosuite/models/assets/textures/steel-brushed.png"/>
    <texture type="2d" name="tex-light-gray-plaster" file="C:\Users/jeise/PycharmProjects/RobotLearningProject/.venv/Lib/site-packages/robosuite/models/assets/textures/light-gray-plaster.png"/>
    <texture type="cube" name="textable" builtin="flat" rgb1="0.5 0.5 0.5" width="512" height="3072"/>
    <texture type="cube" name="Door_light-wood" file="C:\Users/jeise/PycharmProjects/RobotLearningProject/textures/light-wood.png"/>
    <texture type="cube" name="Door_dark-wood" file="C:\Users/jeise/PycharmProjects/RobotLearningProject/textures/wall-12-scandinavia-TEX.png"/>
    <texture type="cube" name="Door_metal" file="C:\Users/jeise/PycharmProjects/RobotLearningProject/textures/brass-ambra.png"/>
    <material name="floorplane" texture="texplane" texuniform="true" texrepeat="2 2" specular="0" shininess="0" reflectance="0.01"/>
    <material name="table_ceramic" texture="tex-ceramic" specular="0.2" shininess="0"/>
    <material name="table_legs_metal" texture="tex-steel-brushed" shininess="0.8" reflectance="0.8"/>
    <material name="walls_mat" texture="tex-light-gray-plaster" texuniform="true" texrepeat="3 3" specular="0.1" shininess="0.1"/>
    <material name="table_mat" texture="textable"/>
    <material name="robot0_Black" shininess="0.25" rgba="0.033102 0.033102 0.033102 1"/>
    <material name="robot0_JointGrey" shininess="0.25" rgba="0.278431 0.278431 0.278431 1"/>
    <material name="robot0_LinkGrey" shininess="0.25" rgba="0.820392 0.820392 0.820392 1"/>
    <material name="robot0_URBlue" shininess="0.25" rgba="0.490196 0.678431 0.8 1"/>
    <material name="Door_MatMetal" texture="Door_metal" specular="1" shininess="0.3" rgba="0.9 0.9 0.9 1"/>
    <material name="Door_MatDarkWood" texture="Door_dark-wood" texrepeat="3 3" specular="0.4" shininess="0.1"/>
    <material name="Door_MatLightWood" texture="Door_light-wood" texrepeat="3 3" specular="0.4" shininess="0.1"/>
    <mesh name="robot0_base_vis_0" file="C:\Users/jeise/PycharmProjects/RobotLearningProject/.venv/Lib/site-packages/robosuite/models/assets/robots/ur5e/obj_meshes/base_vis/base_vis_0.obj"/>
    <mesh name="robot0_base_vis_1" file="C:\Users/jeise/PycharmProjects/RobotLearningProject/.venv/Lib/site-packages/robosuite/models/assets/robots/ur5e/obj_meshes/base_vis/base_vis_1.obj"/>
    <mesh name="robot0_forearm_vis_0" file="C:\Users/jeise/PycharmProjects/RobotLearningProject/.venv/Lib/site-packages/robosuite/models/assets/robots/ur5e/obj_meshes/forearm_vis/forearm_vis_0.obj"/>
    <mesh name="robot0_forearm_vis_1" file="C:\Users/jeise/PycharmProjects/RobotLearningProject/.venv/Lib/site-packages/robosuite/models/assets/robots/ur5e/obj_meshes/forearm_vis/forearm_vis_1.obj"/>
    <mesh name="robot0_forearm_vis_2" file="C:\Users/jeise/PycharmProjects/RobotLearningProject/.venv/Lib/site-packages/robosuite/models/assets/robots/ur5e/obj_meshes/forearm_vis/forearm_vis_2.obj"/>
    <mesh name="robot0_forearm_vis_3" file="C:\Users/jeise/PycharmProjects/RobotLearningProject/.venv/Lib/site-packages/robosuite/models/assets/robots/ur5e/obj_meshes/forearm_vis/forearm_vis_3.obj"/>
    <mesh name="robot0_shoulder_vis_0" file="C:\Users/jeise/PycharmProjects/RobotLearningProject/.venv/Lib/site-packages/robosuite/models/assets/robots/ur5e/obj_meshes/shoulder_vis/shoulder_vis_0.obj"/>
    <mesh name="robot0_shoulder_vis_1" file="C:\Users/jeise/PycharmProjects/RobotLearningProject/.venv/Lib/site-packages/robosuite/models/assets/robots/ur5e/obj_meshes/shoulder_vis/shoulder_vis_1.obj"/>
    <mesh name="robot0_shoulder_vis_2" file="C:\Users/jeise/PycharmProjects/RobotLearningProject/.venv/Lib/site-packages/robosuite/models/assets/robots/ur5e/obj_meshes/shoulder_vis/shoulder_vis_2.obj"/>
    <mesh name="robot0_upperarm_vis_0" file="C:\Users/jeise/PycharmProjects/RobotLearningProject/.venv/Lib/site-packages/robosuite/models/assets/robots/ur5e/obj_meshes/upperarm_vis/upperarm_vis_0.obj"/>
    <mesh name="robot0_upperarm_vis_1" file="C:\Users/jeise/PycharmProjects/RobotLearningProject/.venv/Lib/site-packages/robosuite/models/assets/robots/ur5e/obj_meshes/upperarm_vis/upperarm_vis_1.obj"/>
    <mesh name="robot0_upperarm_vis_2" file="C:\Users/jeise/PycharmProjects/RobotLearningProject/.venv/Lib/site-packages/robosuite/models/assets/robots/ur5e/obj_meshes/upperarm_vis/upperarm_vis_2.obj"/>
    <mesh name="robot0_upperarm_vis_3" file="C:\Users/jeise/PycharmProjects/RobotLearningProject/.venv/Lib/site-packages/robosuite/models/assets/robots/ur5e/obj_meshes/upperarm_vis/upperarm_vis_3.obj"/>
    <mesh name="robot0_wrist1_vis_0" file="C:\Users/jeise/PycharmProjects/RobotLearningProject/.venv/Lib/site-packages/robosuite/models/assets/robots/ur5e/obj_meshes/wrist1_vis/wrist1_vis_0.obj"/>
    <mesh name="robot0_wrist1_vis_1" file="C:\Users/jeise/PycharmProjects/RobotLearningProject/.venv/Lib/site-packages/robosuite/models/assets/robots/ur5e/obj_meshes/wrist1_vis/wrist1_vis_1.obj"/>
    <mesh name="robot0_wrist1_vis_2" file="C:\Users/jeise/PycharmProjects/RobotLearningProject/.venv/Lib/site-packages/robosuite/models/assets/robots/ur5e/obj_meshes/wrist1_vis/wrist1_vis_2.obj"/>
    <mesh name="robot0_wrist2_vis_0" file="C:\Users/jeise/PycharmProjects/RobotLearningProject/.venv/Lib/site-packages/robosuite/models/assets/robots/ur5e/obj_meshes/wrist2_vis/wrist2_vis_0.obj"/>
    <mesh name="robot0_wrist2_vis_1" file="C:\Users/jeise/PycharmProjects/RobotLearningProject/.venv/Lib/site-packages/robosuite/models/assets/robots/ur5e/obj_meshes/wrist2_vis/wrist2_vis_1.obj"/>
    <mesh name="robot0_wrist2_vis_2" file="C:\Users/jeise/PycharmProjects/RobotLearningProject/.venv/Lib/site-packages/robosuite/models/assets/robots/ur5e/obj_meshes/wrist2_vis/wrist2_vis_2.obj"/>
    <mesh name="robot0_wrist3_vis" file="C:\Users/jeise/PycharmProjects/RobotLearningProject/.venv/Lib/site-packages/robosuite/models/assets/robots/ur5e/obj_meshes/wrist3_vis/wrist3_vis.obj"/>
    <mesh name="robot0_base" file="C:\Users/jeise/PycharmProjects/RobotLearningProject/.venv/Lib/site-packages/robosuite/models/assets/robots/ur5e/meshes/base.stl"/>
    <mesh name="robot0_shoulder" file="C:\Users/jeise/PycharmProjects/RobotLearningProject/.venv/Lib/site-packages/robosuite/models/assets/robots/ur5e/meshes/shoulder.stl"/>
    <mesh name="robot0_upperarm" file="C:\Users/jeise/PycharmProjects/RobotLearningProject/.venv/Lib/site-packages/robosuite/models/assets/robots/ur5e/meshes/upperarm.stl"/>
    <mesh name="robot0_forearm" file="C:\Users/jeise/PycharmProjects/RobotLearningProject/.venv/Lib/site-packages/robosuite/models/assets/robots/ur5e/meshes/forearm.stl"/>
    <mesh name="robot0_wrist1" file="C:\Users/jeise/PycharmProjects/RobotLearningProject/.venv/Lib/site-packages/robosuite/models/assets/robots/ur5e/meshes/wrist1.stl"/>
    <mesh name="robot0_wrist2" file="C:\Users/jeise/PycharmProjects/RobotLearningProject/.venv/Lib/site-packages/robosuite/models/assets/robots/ur5e/meshes/wrist2.stl"/>
    <mesh name="robot0_wrist3" file="C:\Users/jeise/PycharmProjects/RobotLearningProject/.venv/Lib/site-packages/robosuite/models/assets/robots/ur5e/meshes/wrist3.stl"/>
    <mesh name="fixed_mount0_pedestal" file="C:\Users/jeise/PycharmProjects/RobotLearningProject/.venv/Lib/site-packages/robosuite/models/assets/bases/meshes/rethink_mount/pedestal.stl"/>
    <mesh name="gripper0_right_robotiq_arg2f_base_link" file="C:\Users/jeise/PycharmProjects/RobotLearningProject/.venv/Lib/site-packages/robosuite/models/assets/grippers/meshes/robotiq_85_gripper/robotiq_arg2f_base_link.stl"/>
    <mesh name="gripper0_right_robotiq_arg2f_85_outer_knuckle" file="C:\Users/jeise/PycharmProjects/RobotLearningProject/.venv/Lib/site-packages/robosuite/models/assets/grippers/meshes/robotiq_85_gripper/robotiq_arg2f_85_outer_knuckle.stl" scale="0.001 0.001 0.001"/>
    <mesh name="gripper0_right_robotiq_arg2f_85_outer_finger" file="C:\Users/jeise/PycharmProjects/RobotLearningProject/.venv/Lib/site-packages/robosuite/models/assets/grippers/meshes/robotiq_85_gripper/robotiq_arg2f_85_outer_finger.stl" scale="0.001 0.001 0.001"/>
    <mesh name="gripper0_right_robotiq_arg2f_85_inner_finger" file="C:\Users/jeise/PycharmProjects/RobotLearningProject/.venv/Lib/site-packages/robosuite/models/assets/grippers/meshes/robotiq_85_gripper/robotiq_arg2f_85_inner_finger.stl" scale="0.001 0.001 0.001"/>
    <mesh name="gripper0_right_robotiq_arg2f_85_inner_knuckle" file="C:\Users/jeise/PycharmProjects/RobotLearningProject/.venv/Lib/site-packages/robosuite/models/assets/grippers/meshes/robotiq_85_gripper/robotiq_arg2f_85_inner_knuckle.stl" scale="0.001 0.001 0.001"/>
    <mesh name="gripper0_right_robotiq_arg2f_85_outer_knuckle_vis" file="C:\Users/jeise/PycharmProjects/RobotLearningProject/.venv/Lib/site-packages/robosuite/models/assets/grippers/meshes/robotiq_85_gripper/robotiq_arg2f_85_outer_knuckle_vis.stl" scale="0.001 0.001 0.001"/>
    <mesh name="gripper0_right_robotiq_arg2f_85_outer_finger_vis" file="C:\Users/jeise/PycharmProjects/RobotLearningProject/.venv/Lib/site-packages/robosuite/models/assets/grippers/meshes/robotiq_85_gripper/robotiq_arg2f_85_outer_finger_vis.stl" scale="0.001 0.001 0.001"/>
    <mesh name="gripper0_right_robotiq_arg2f_85_inner_finger_vis" file="C:\Users/jeise/PycharmProjects/RobotLearningProject/.venv/Lib/site-packages/robosuite/models/assets/grippers/meshes/robotiq_85_gripper/robotiq_arg2f_85_inner_finger_vis.stl" scale="0.001 0.001 0.001"/>
    <mesh name="gripper0_right_robotiq_arg2f_85_inner_knuckle_vis" file="C:\Users/jeise/PycharmProjects/RobotLearningProject/.venv/Lib/site-packages/robosuite/models/assets/grippers/meshes/robotiq_85_gripper/robotiq_arg2f_85_inner_knuckle_vis.stl" scale="0.001 0.001 0.001"/>
  </asset>

  <worldbody>
    <geom name="floor" size="3 3 0.125" type="plane" group="1" material="floorplane"/>
    <geom name="wall_leftcorner_visual" size="1.06 1.5 0.01" pos="-1.25 2.25 1.5" quat="0.653281 0.653281 0.270598 0.270598" type="box" contype="0" conaffinity="0" group="1" material="walls_mat"/>
    <geom name="wall_rightcorner_visual" size="1.06 1.5 0.01" pos="-1.25 -2.25 1.5" quat="0.653281 0.653281 -0.270598 -0.270598" type="box" contype="0" conaffinity="0" group="1" material="walls_mat"/>
    <geom name="wall_left_visual" size="1.75 1.5 0.01" pos="1.25 3 1.5" quat="0.707107 0.707107 0 0" type="box" contype="0" conaffinity="0" group="1" material="walls_mat"/>
    <geom name="wall_right_visual" size="1.75 1.5 0.01" pos="1.25 -3 1.5" quat="0.707107 -0.707107 0 0" type="box" contype="0" conaffinity="0" group="1" material="walls_mat"/>
    <geom name="wall_rear_visual" size="1.5 1.5 0.01" pos="-2 0 1.5" quat="0.5 0.5 0.5 0.5" type="box" contype="0" conaffinity="0" group="1" material="walls_mat"/>
    <geom name="wall_front_visual" size="3 1.5 0.01" pos="3 0 1.5" quat="0.5 0.5 -0.5 -0.5" type="box" contype="0" conaffinity="0" group="1" material="walls_mat"/>
    <camera name="frontview" pos="1.6 0 1.45" quat="0.560842 0.430646 0.430646 0.560842"/>
    <camera name="birdview" pos="-0.2 0 3" quat="0.707107 0 0 0.707107"/>
    <camera name="agentview" pos="0.598613 -4.39204e-09 1.59035" quat="0.638018 0.30485 0.30485 0.638018"/>
    <camera name="sideview" pos="-0.0565177 1.27612 1.48796" quat="0.00990507 0.00687796 0.591223 0.806418"/>
    <light pos="1 1 1.5" dir="-0.19245 -0.19245 -0.96225" directional="true" castshadow="false"/>
    <body name="table" pos="-0.2 -0.35 0.775">
      <geom name="table_collision" size="0.4 0.15 0.025" type="box" rgba="0.5 0.5 0 1"/>
      <geom name="table_visual" size="0.4 0.15 0.025" type="box" contype="0" conaffinity="0" group="1" material="table_ceramic"/>
      <geom name="table_leg1_visual" size="0.025 0.3875" pos="0.3 0 -0.3875" type="cylinder" contype="0" conaffinity="0" group="1" material="table_legs_metal"/>
      <geom name="table_leg2_visual" size="0.025 0.3875" pos="-0.3 0 -0.3875" type="cylinder" contype="0" conaffinity="0" group="1" material="table_legs_metal"/>
      <geom name="table_leg3_visual" size="0.025 0.3875" pos="-0.3 0 -0.3875" type="cylinder" contype="0" conaffinity="0" group="1" material="table_legs_metal"/>
      <geom name="table_leg4_visual" size="0.025 0.3875" pos="0.3 0 -0.3875" type="cylinder" contype="0" conaffinity="0" group="1" material="table_legs_metal"/>
      <site name="table_top" pos="0 0 0.025" size="0.001" rgba="0 0 0 0"/>
    </body>
    <body name="left_eef_target" pos="0 0 -1" mocap="true">
      <geom name="left_eef_target_box" size="0.05 0.05 0.05" type="box" contype="0" conaffinity="0" group="2" rgba="0.898 0.42 0.435 0.5"/>
      <geom name="left_eef_target_sphere" size="0.01" contype="0" conaffinity="0" group="2" rgba="0.898 0.42 0.435 0.8"/>
    </body>
    <body name="right_eef_target" pos="0 0 -1" mocap="true">
      <geom name="right_eef_target_box" size="0.05 0.05 0.05" type="box" contype="0" conaffinity="0" group="2" rgba="0.208 0.314 0.439 0.5"/>
      <geom name="right_eef_target_sphere" size="0.01" contype="0" conaffinity="0" group="2" rgba="0.208 0.314 0.439 0.8"/>
    </body>
    <body name="robot0_base" pos="-0.56 0 0.912">
      <inertial pos="0 0 0" mass="0" diaginertia="0 0 0"/>
      <camera name="robot0_robotview" pos="1 0 0.4" quat="0.653098 0.271041 0.271041 0.653098"/>
      <body name="robot0_fixed_base_link">
        <geom name="robot0_g0_vis" type="mesh" contype="0" conaffinity="0" group="1" material="robot0_Black" mesh="robot0_base_vis_0"/>
        <geom name="robot0_g1_vis" type="mesh" contype="0" conaffinity="0" group="1" material="robot0_JointGrey" mesh="robot0_base_vis_1"/>
        <geom name="robot0_base_col" type="mesh" rgba="0 0.5 0 1" mesh="robot0_base"/>
        <site name="robot0_right_center" pos="0 0 0" size="0.01" group="2" rgba="1 0.3 0.3 1"/>
        <body name="robot0_shoulder_link" pos="0 0 0.163">
          <inertial pos="0 0 0" mass="3.7" diaginertia="0.0102675 0.0102675 0.00666"/>
          <joint name="robot0_shoulder_pan_joint" pos="0 0 0" axis="0 0 1" limited="true" range="-6.28319 6.28319" armature="5" damping="0.001" frictionloss="0.01"/>
          <geom name="robot0_g2_vis" type="mesh" contype="0" conaffinity="0" group="1" material="robot0_URBlue" mesh="robot0_shoulder_vis_0"/>
          <geom name="robot0_g3_vis" type="mesh" contype="0" conaffinity="0" group="1" material="robot0_Black" mesh="robot0_shoulder_vis_1"/>
          <geom name="robot0_g4_vis" type="mesh" contype="0" conaffinity="0" group="1" material="robot0_JointGrey" mesh="robot0_shoulder_vis_2"/>
          <geom name="robot0_shoulder_col" type="mesh" rgba="0 0.5 0 1" mesh="robot0_shoulder"/>
          <body name="robot0_upper_arm_link" pos="0 0.138 0" quat="0.707107 0 0.707107 0">
            <inertial pos="0 0 0.2125" mass="8.393" diaginertia="0.133886 0.133886 0.0151074"/>
            <joint name="robot0_shoulder_lift_joint" pos="0 0 0" axis="0 1 0" limited="true" range="-6.28319 6.28319" armature="2.5" damping="0.001" frictionloss="0.01"/>
            <geom name="robot0_g5_vis" type="mesh" contype="0" conaffinity="0" group="1" material="robot0_LinkGrey" mesh="robot0_upperarm_vis_0"/>
            <geom name="robot0_g6_vis" type="mesh" contype="0" conaffinity="0" group="1" material="robot0_Black" mesh="robot0_upperarm_vis_1"/>
            <geom name="robot0_g7_vis" type="mesh" contype="0" conaffinity="0" group="1" material="robot0_JointGrey" mesh="robot0_upperarm_vis_2"/>
            <geom name="robot0_g8_vis" type="mesh" contype="0" conaffinity="0" group="1" material="robot0_URBlue" mesh="robot0_upperarm_vis_3"/>
            <geom name="robot0_upperarm_col" type="mesh" rgba="0 0.5 0 1" mesh="robot0_upperarm"/>
            <body name="robot0_forearm_link" pos="0 -0.131 0.425">
              <inertial pos="0 0 0.196" mass="2.275" diaginertia="0.0311796 0.0311796 0.004095"/>
              <joint name="robot0_elbow_joint" pos="0 0 0" axis="0 1 0" limited="true" range="-3.14159 3.14159" armature="1.66667" damping="0.001" frictionloss="0.01"/>
              <geom name="robot0_g9_vis" type="mesh" contype="0" conaffinity="0" group="1" material="robot0_URBlue" mesh="robot0_forearm_vis_0"/>
              <geom name="robot0_g10_vis" type="mesh" contype="0" conaffinity="0" group="1" material="robot0_LinkGrey" mesh="robot0_forearm_vis_1"/>
              <geom name="robot0_g11_vis" type="mesh" contype="0" conaffinity="0" group="1" material="robot0_Black" mesh="robot0_forearm_vis_2"/>
              <geom name="robot0_g12_vis" type="mesh" contype="0" conaffinity="0" group="1" material="robot0_JointGrey" mesh="robot0_forearm_vis_3"/>
              <geom name="robot0_forearm_col" type="mesh" rgba="0 0.5 0 1" mesh="robot0_forearm"/>
              <body name="robot0_wrist_1_link" pos="0 0 0.392" quat="0.707107 0 0.707107 0">
                <inertial pos="0 0.127 0" mass="1.219" diaginertia="0.0025599 0.0025599 0.0021942"/>
                <joint name="robot0_wrist_1_joint" pos="0 0 0" axis="0 1 0" limited="true" range="-6.28319 6.28319" armature="1.25" damping="0.001" frictionloss="0.01"/>
                <geom name="robot0_g13_vis" type="mesh" contype="0" conaffinity="0" group="1" material="robot0_Black" mesh="robot0_wrist1_vis_0"/>
                <geom name="robot0_g14_vis" type="mesh" contype="0" conaffinity="0" group="1" material="robot0_URBlue" mesh="robot0_wrist1_vis_1"/>
                <geom name="robot0_g15_vis" type="mesh" contype="0" conaffinity="0" group="1" material="robot0_JointGrey" mesh="robot0_wrist1_vis_2"/>
                <geom name="robot0_wrist1_col" type="mesh" rgba="0 0.5 0 1" mesh="robot0_wrist1"/>
                <body name="robot0_wrist_2_link" pos="0 0.127 0">
                  <inertial pos="0 0 0.1" mass="1.219" diaginertia="0.0025599 0.0025599 0.0021942"/>
                  <joint name="robot0_wrist_2_joint" pos="0 0 0" axis="0 0 1" limited="true" range="-6.28319 6.28319" armature="1" damping="0.001" frictionloss="0.01"/>
                  <geom name="robot0_g16_vis" type="mesh" contype="0" conaffinity="0" group="1" material="robot0_Black" mesh="robot0_wrist2_vis_0"/>
                  <geom name="robot0_g17_vis" type="mesh" contype="0" conaffinity="0" group="1" material="robot0_URBlue" mesh="robot0_wrist2_vis_1"/>
                  <geom name="robot0_g18_vis" type="mesh" contype="0" conaffinity="0" group="1" material="robot0_JointGrey" mesh="robot0_wrist2_vis_2"/>
                  <geom name="robot0_wrist2_col" type="mesh" rgba="0 0.5 0 1" mesh="robot0_wrist2"/>
                  <body name="robot0_wrist_3_link" pos="0 0 0.1">
                    <inertial pos="0 0.0771683 0" quat="0.707107 0 0 0.707107" mass="0.1889" diaginertia="0.000132134 9.90863e-05 9.90863e-05"/>
                    <joint name="robot0_wrist_3_joint" pos="0 0 0" axis="0 1 0" limited="true" range="-6.28319 6.28319" armature="0.833333" damping="0.001" frictionloss="0.01"/>
                    <geom name="robot0_g19_vis" type="mesh" contype="0" conaffinity="0" group="1" material="robot0_LinkGrey" mesh="robot0_wrist3_vis"/>
                    <geom name="robot0_wrist3_col" type="mesh" rgba="0 0.5 0 1" mesh="robot0_wrist3"/>
                    <geom name="robot0_wrist3_col2" size="0.005 0.005 0.005" pos="0 0.09 0" quat="0.707107 0 0 0.707107" type="box" rgba="0 0.5 0 1"/>
                    <body name="robot0_right_hand" pos="0 0.098 0" quat="0.707107 -0.707107 0 0">
                      <camera name="robot0_eye_in_hand" pos="0.05 0 0" quat="0 0.707107 0.707107 0" fovy="75"/>
                      <body name="gripper0_right_robotiq_85_adapter_link">
                        <inertial pos="0 0 0" mass="0.01" diaginertia="0.001 0.001 0.001"/>
                        <geom name="gripper0_right_hand_visual" type="mesh" contype="0" conaffinity="0" group="1" rgba="0.1 0.1 0.1 1" mesh="gripper0_right_robotiq_arg2f_base_link"/>
                        <geom name="gripper0_right_hand_collision" type="mesh" rgba="0 0 0.5 1" mesh="gripper0_right_robotiq_arg2f_base_link"/>
                        <site name="gripper0_right_ft_frame" pos="0 0 0" size="0.01" group="1" rgba="1 0 0 1"/>
                        <body name="gripper0_right_eef" pos="0 0 0.145" quat="0.707107 0 0 -0.707107">
                          <site name="gripper0_right_grip_site" pos="0 0 0" size="0.01" group="1" rgba="0.999999 6.06731e-07 0 0.5"/>
                          <site name="gripper0_right_ee_x" pos="0.1 0 0" quat="0.707105 0 0.707108 0" size="0.005 0.1" group="1" type="cylinder" rgba="1 0 0 0"/>
                          <site name="gripper0_right_ee_y" pos="0 0.1 0" quat="0.707105 0.707108 0 0" size="0.005 0.1" group="1" type="cylinder" rgba="0 1 0 0"/>
                          <site name="gripper0_right_ee_z" pos="0 0 0.1" size="0.005 0.1" group="1" type="cylinder" rgba="0 0 1 0"/>
                          <site name="gripper0_right_grip_site_cylinder" pos="0 0 0" size="0.005 10" group="1" type="cylinder" rgba="0 1 0 0.3"/>
                        </body>
                        <body name="gripper0_right_left_outer_knuckle" pos="0 -0.0306011 0.054904" quat="0 0 0 1">
                          <inertial pos="0.000163875 0.0554825 -0.0100755" quat="0.920541 0.390623 -0.00362953 0.00231744" mass="0.0311462" diaginertia="5.11372e-05 4.89464e-05 4.95906e-06"/>
                          <joint name="gripper0_right_finger_joint" pos="0 0 0" axis="1 0 0" limited="true" range="0 0.8"/>
                          <geom name="gripper0_right_left_outer_knuckle_visual" type="mesh" contype="0" conaffinity="0" group="1" rgba="0.792157 0.819608 0.933333 1" mesh="gripper0_right_robotiq_arg2f_85_outer_knuckle_vis"/>
                          <geom name="gripper0_right_left_outer_knuckle_collision" type="mesh" solref="0.01 0.25" rgba="0 0 0.5 1" mesh="gripper0_right_robotiq_arg2f_85_outer_knuckle"/>
                          <geom name="gripper0_right_left_outer_finger_visual" pos="0 0.0315 -0.0041" quat="1 0 0 0" type="mesh" contype="0" conaffinity="0" group="1" rgba="0.1 0.1 0.1 1" mesh="gripper0_right_robotiq_arg2f_85_outer_finger_vis"/>
                          <geom name="gripper0_right_left_outer_finger_collision" pos="0 0.0315 -0.0041" quat="1 0 0 0" type="mesh" solref="0.01 0.25" rgba="0 0 0.5 1" mesh="gripper0_right_robotiq_arg2f_85_outer_finger"/>
                          <body name="gripper0_right_left_inner_finger" pos="0 0.0376 0.043">
                            <inertial pos="0.000199506 0.0032692 0.00175282" quat="0.933621 0.35825 -0.00273441 0.00104851" mass="0.0156391" diaginertia="1.57977e-05 1.51089e-05 1.4647e-06"/>
                            <joint name="gripper0_right_left_inner_finger_joint" pos="0 0 0" axis="1 0 0" limited="true" range="-0.8757 0.8757"/>
                            <geom name="gripper0_right_left_inner_finger_visual" type="mesh" contype="0" conaffinity="0" group="1" rgba="0.1 0.1 0.1 1" mesh="gripper0_right_robotiq_arg2f_85_inner_finger_vis"/>
                            <geom name="gripper0_right_left_inner_finger_collision" type="mesh" solref="0.01 0.25" rgba="0 0 0.5 1" mesh="gripper0_right_robotiq_arg2f_85_inner_finger"/>
                            <geom name="gripper0_right_left_fingertip_visual" size="0.011 0.003175 0.01875" pos="0 -0.0220203 0.03242" type="box" contype="0" conaffinity="0" group="1" rgba="0.9 0.9 0.9 1"/>
                            <geom name="gripper0_right_left_fingertip_collision" size="0.011 0.003175 0.01875" pos="0 -0.0220203 0.03242" type="box" solref="0.01 0.25" rgba="0 0 0.5 1"/>
                            <geom name="gripper0_right_left_fingerpad_collision" size="0.01 0.001 0.01675" pos="0 -0.0245203 0.03242" type="box" rgba="0 0 0.5 1"/>
                          </body>
                        </body>
                        <body name="gripper0_right_left_inner_knuckle" pos="0 -0.0127 0.06142" quat="0 0 0 1">
                          <inertial pos="0.000123012 0.0507851 0.00103969" quat="0.497203 0.502496 -0.507943 0.492221" mass="0.0271177" diaginertia="2.83809e-05 2.61936e-05 2.81319e-06"/>
                          <joint name="gripper0_right_left_inner_knuckle_joint" pos="0 0 0" axis="1 0 0" limited="true" range="0 0.8757"/>
                          <geom name="gripper0_right_left_inner_knuckle_visual" type="mesh" contype="0" conaffinity="0" group="1" rgba="0.1 0.1 0.1 1" mesh="gripper0_right_robotiq_arg2f_85_inner_knuckle_vis"/>
                          <geom name="gripper0_right_left_inner_knuckle_collision" type="mesh" rgba="0 0 0.5 1" mesh="gripper0_right_robotiq_arg2f_85_inner_knuckle"/>
                        </body>
                        <body name="gripper0_right_right_outer_knuckle" pos="0 0.0306011 0.054904">
                          <inertial pos="0.000163875 0.0554825 -0.0100755" quat="0.920541 0.390623 -0.00362953 0.00231744" mass="0.0311462" diaginertia="5.11372e-05 4.89464e-05 4.95906e-06"/>
                          <joint name="gripper0_right_right_outer_knuckle_joint" pos="0 0 0" axis="1 0 0" limited="true" range="0 0.8"/>
                          <geom name="gripper0_right_right_outer_knuckle_visual" type="mesh" contype="0" conaffinity="0" group="1" rgba="0.792157 0.819608 0.933333 1" mesh="gripper0_right_robotiq_arg2f_85_outer_knuckle_vis"/>
                          <geom name="gripper0_right_right_outer_knuckle_collision" type="mesh" solref="0.01 0.25" rgba="0 0 0.5 1" mesh="gripper0_right_robotiq_arg2f_85_outer_knuckle"/>
                          <geom name="gripper0_right_right_outer_finger_visual" pos="0 0.0315 -0.0041" quat="1 0 0 0" type="mesh" contype="0" conaffinity="0" group="1" rgba="0.1 0.1 0.1 1" mesh="gripper0_right_robotiq_arg2f_85_outer_finger_vis"/>
                          <geom name="gripper0_right_right_outer_finger_collision" pos="0 0.0315 -0.0041" quat="1 0 0 0" type="mesh" solref="0.01 0.25" rgba="0 0 0.5 1" mesh="gripper0_right_robotiq_arg2f_85_outer_finger"/>
                          <body name="gripper0_right_right_inner_finger" pos="0 0.0376 0.043">
                            <inertial pos="0.000199506 0.0032692 0.00175282" quat="0.933621 0.35825 -0.00273441 0.00104851" mass="0.0156391" diaginertia="1.57977e-05 1.51089e-05 1.4647e-06"/>
                            <joint name="gripper0_right_right_inner_finger_joint" pos="0 0 0" axis="1 0 0" limited="true" range="-0.8757 0.8757"/>
                            <geom name="gripper0_right_right_inner_finger_visual" type="mesh" contype="0" conaffinity="0" group="1" rgba="0.1 0.1 0.1 1" mesh="gripper0_right_robotiq_arg2f_85_inner_finger_vis"/>
                            <geom name="gripper0_right_right_inner_finger_collision" type="mesh" solref="0.01 0.25" rgba="0 0 0.5 1" mesh="gripper0_right_robotiq_arg2f_85_inner_finger"/>
                            <geom name="gripper0_right_right_fingertip_visual" size="0.011 0.003175 0.01875" pos="0 -0.0220203 0.03242" type="box" contype="0" conaffinity="0" group="1" rgba="0.9 0.9 0.9 1"/>
                            <geom name="gripper0_right_right_fingertip_collision" size="0.011 0.003175 0.01875" pos="0 -0.0220203 0.03242" type="box" solref="0.01 0.25" rgba="0 0 0.5 1"/>
                            <geom name="gripper0_right_right_fingerpad_collision" size="0.01 0.001 0.01675" pos="0 -0.0245203 0.03242" type="box" rgba="0 0 0.5 1"/>
                          </body>
                        </body>
                        <body name="gripper0_right_right_inner_knuckle" pos="0 0.0127 0.06142">
                          <inertial pos="0.000123012 0.0507851 0.00103969" quat="0.497203 0.502496 -0.507943 0.492221" mass="0.0271177" diaginertia="2.83809e-05 2.61936e-05 2.81319e-06"/>
                          <joint name="gripper0_right_right_inner_knuckle_joint" pos="0 0 0" axis="1 0 0" limited="true" range="0 0.8757"/>
                          <geom name="gripper0_right_right_inner_knuckle_visual" type="mesh" contype="0" conaffinity="0" group="1" rgba="0.1 0.1 0.1 1" mesh="gripper0_right_robotiq_arg2f_85_inner_knuckle_vis"/>
                          <geom name="gripper0_right_right_inner_knuckle_collision" type="mesh" rgba="0 0 0.5 1" mesh="gripper0_right_robotiq_arg2f_85_inner_knuckle"/>
                        </body>
                      </body>
                    </body>
                  </body>
                </body>
              </body>
            </body>
          </body>
        </body>
      </body>
      <body name="fixed_mount0_base" pos="0 0 0.01">
        <body name="fixed_mount0_controller_box">
          <inertial pos="-0.325 0 -0.38" mass="46.64" diaginertia="1.71363 1.27988 0.809981"/>
          <geom name="fixed_mount0_controller_box_col" size="0.11 0.2 0.265" pos="-0.325 0 -0.38" type="box" rgba="0.5 0.5 0 1"/>
        </body>
        <body name="fixed_mount0_pedestal_feet">
          <inertial pos="-0.1225 0 -0.758" mass="167.09" diaginertia="8.16095 9.59375 15.0785"/>
          <geom name="fixed_mount0_pedestal_feet_col" size="0.385 0.35 0.155" pos="-0.1225 0 -0.758" type="box" rgba="0.5 0.5 0 1"/>
        </body>
        <body name="fixed_mount0_torso">
          <inertial pos="0 0 0" mass="0.0001" diaginertia="1e-08 1e-08 1e-08"/>
          <geom name="fixed_mount0_torso_vis" size="0.05 0.05 0.05" pos="0 0 -0.05" type="box" contype="0" conaffinity="0" group="1" rgba="0.2 0.2 0.2 1"/>
        </body>
        <body name="fixed_mount0_pedestal">
          <inertial pos="0 0 0" quat="0.659267 -0.259505 -0.260945 0.655692" mass="60.864" diaginertia="6.0869 5.81635 4.20915"/>
          <geom name="fixed_mount0_pedestal_vis" type="mesh" contype="0" conaffinity="0" group="1" rgba="0.2 0.2 0.2 1" mesh="fixed_mount0_pedestal"/>
          <geom name="fixed_mount0_pedestal_col" size="0.18 0.31" pos="-0.02 0 -0.29" type="cylinder" rgba="0.5 0.5 0 1"/>
        </body>
      </body>
    </body>
    <body name="Door_main" pos="-0.111246 -0.342384 1.1" quat="0.704137 0 0 -0.710064">
      <site name="Door_default_site" pos="0 0 0" size="0.002" rgba="1 0 0 0"/>
      <body name="Door_frame" pos="0 0.22 0" quat="0.707388 0 0 -0.706825">
        <inertial pos="0.3 0 0" quat="0.5 0.5 0.5 0.5" mass="7.85398" diaginertia="0.923301 0.764585 0.168533"/>
        <geom name="Door_r_frame" size="0.03 0.3" pos="0.555 0 0" type="cylinder" rgba="0.5 0 0 1"/>
        <geom name="Door_l_frame" size="0.03 0.3" pos="0.045 0 0" type="cylinder" rgba="0.5 0 0 1"/>
        <geom name="Door_r_frame_visual" size="0.03 0.3" pos="0.555 0 0" type="cylinder" contype="0" conaffinity="0" group="1" mass="0" rgba="1 1 1 1"/>
        <geom name="Door_l_frame_visual" size="0.03 0.3" pos="0.045 0 0" type="cylinder" contype="0" conaffinity="0" group="1" mass="0" rgba="1 1 1 1"/>
        <body name="Door_door" pos="0.3 0 0">
          <inertial pos="0.0296816 -0.00152345 0" quat="0.701072 0 0 0.713091" mass="2.43455" diaginertia="0.0913751 0.0521615 0.043714"/>
          <joint name="Door_hinge" pos="0.255 0 0" axis="0 0 1" limited="true" range="0 0.4" damping="0.1"/>
          <geom name="Door_panel" size="0.22 0.02 0.29" type="box" friction="1 1 1" rgba="0.5 0 0 1"/>
          <geom name="Door_panel_visual" size="0.22 0.02 0.29" type="box" contype="0" conaffinity="0" group="1" friction="1 1 1" mass="0" material="Door_MatDarkWood"/>
          <body name="Door_latch" pos="-0.175 0 -0.025">
            <inertial pos="-0.017762 0.0138544 0" quat="0.365653 0.605347 -0.36522 0.605365" mass="0.1" diaginertia="0.0483771 0.0410001 0.0111013"/>
            <joint name="Door_latch_joint" pos="0 0 0" axis="0 1 0" stiffness="1" limited="true" range="-1.57 1.57" frictionloss="0.1"/>
            <geom name="Door_handle_base" size="0.025 0.09375" pos="0 -0.03125 0" quat="0.707107 -0.707107 0 0" type="cylinder" rgba="0.5 0 0 1"/>
            <geom name="Door_handle" size="0.075 0.015 0.02" pos="0.075 -0.1 0" type="box" rgba="0.5 0 0 1"/>
            <geom name="Door_latch" size="0.025 0.0125 0.03125" pos="-0.03125 0.05 0" quat="0.707388 0 0.706825 0" type="box" rgba="0.5 0 0 1"/>
            <geom name="Door_latch_tip" size="0.025 0.0125" pos="-0.0625 0.05 0" quat="0.707388 0.706825 0 0" type="cylinder" rgba="0.5 0 0 1"/>
            <geom name="Door_handle_base_visual" size="0.025 0.09375" pos="0 -0.03125 0" quat="0.707107 -0.707107 0 0" type="cylinder" contype="0" conaffinity="0" group="1" mass="0" material="Door_MatMetal"/>
            <geom name="Door_handle_visual" size="0.075 0.015 0.02" pos="0.075 -0.1 0" type="box" contype="0" conaffinity="0" group="1" mass="0" material="Door_MatMetal"/>
            <geom name="Door_latch_visual" size="0.025 0.0125 0.03125" pos="-0.03125 0.05 0" quat="0.707388 0 0.706825 0" type="box" contype="0" conaffinity="0" group="1" mass="0" material="Door_MatMetal"/>
            <geom name="Door_latch_tip_visual" size="0.025 0.0125" pos="-0.0625 0.05 0" quat="0.707388 0.706825 0 0" type="cylinder" contype="0" conaffinity="0" group="1" mass="0" material="Door_MatMetal"/>
            <site name="Door_handle" pos="0.125 -0.1 0" size="0.02" rgba="0 0 1 0"/>
          </body>
        </body>
      </body>
      <body name="Door_red_cube" pos="-0.23 0.1 -0.15">
        <inertial pos="0.3 0 0" quat="0.5 0.5 0.5 0.5" mass="7.85398" diaginertia="0.923301 0.764585 0.168533"/>
        <joint name="Door_cube_joint" pos="0 0 0" axis="0 1 0" type="slide"/>
        <geom name="Door_g7" size="0.1 0.1 0.1" type="box" group="1" friction="0.33" rgba="1 0 0 1"/>
      </body>
    </body>
  </worldbody>

  <tendon>
    <fixed name="gripper0_right_finger2_12_cpl" limited="true" range="-1 1" stiffness="0.4" springlength="0.001">
      <joint joint="gripper0_right_finger_joint" coef="1"/>
      <joint joint="gripper0_right_left_inner_finger_joint" coef="-3"/>
      <joint joint="gripper0_right_left_inner_knuckle_joint" coef="1"/>
    </fixed>
    <fixed name="gripper0_right_finger1_12_cpl" limited="true" range="-1 1" stiffness="0.4" springlength="0.001">
      <joint joint="gripper0_right_right_outer_knuckle_joint" coef="1"/>
      <joint joint="gripper0_right_right_inner_finger_joint" coef="-3"/>
      <joint joint="gripper0_right_right_inner_knuckle_joint" coef="1"/>
    </fixed>
  </tendon>

  <actuator>
    <general name="robot0_torq_j1" joint="robot0_shoulder_pan_joint" ctrllimited="true" ctrlrange="-150 150"/>
    <general name="robot0_torq_j2" joint="robot0_shoulder_lift_joint" ctrllimited="true" ctrlrange="-150 150"/>
    <general name="robot0_torq_j3" joint="robot0_elbow_joint" ctrllimited="true" ctrlrange="-150 150"/>
    <general name="robot0_torq_j4" joint="robot0_wrist_1_joint" ctrllimited="true" ctrlrange="-28 28"/>
    <general name="robot0_torq_j5" joint="robot0_wrist_2_joint" ctrllimited="true" ctrlrange="-28 28"/>
    <general name="robot0_torq_j6" joint="robot0_wrist_3_joint" ctrllimited="true" ctrlrange="-28 28"/>
    <general name="gripper0_right_finger_1" joint="gripper0_right_finger_joint" ctrllimited="true" ctrlrange="0 0.8" biastype="affine" gainprm="20" biasprm="0 -20"/>
    <general name="gripper0_right_finger_2" joint="gripper0_right_right_outer_knuckle_joint" ctrllimited="true" ctrlrange="0 0.8" biastype="affine" gainprm="20" biasprm="0 -20"/>
  </actuator>

  <sensor>
    <force site="gripper0_right_ft_frame" name="gripper0_right_force_ee"/>
    <torque site="gripper0_right_ft_frame" name="gripper0_right_torque_ee"/>
  </sensor>
</mujoco>
